Workbook

Sheet WindTurbineConfiguration
A1: Baseline 20 MW
A7: Class and Category | B7: IEC Class 1C
A8: Rotor Rotation | B8: Clockwise rotation
A9: Rotor Orientation | B9: Upwind
A10: Number of Blades | B10: 3
A11: Control | B11: Variable speed collective pitch
A12: Drivetrain | B12: Single Stage
A13: Rated Mechanical Power | B13: 21.276596 | C13: [MW]
A14: Rotor Diameter | B14: 252.2 | C14: [m]
A15: Hub Height | B15: 167.93 | C15: [m]
A16: Rotor Cone Angle | B16: 2.5 | C16: [deg]
A17: Nacelle Uptilt Angle | B17: 5 | C17: [deg]
A18: Rotor Overhang | B18: 10.04 | C18: [m]
A19: Length Blade Root Flange | B19: 3.96 | C19: [m]
A20: Hub Mass | B20: 278470 | C20: [kg]
A21: Nacelle Mass | B21: 1098270 | C21: [kg]
A22: Generator Mass | B22: 0 | C22: [kg]
A23: Blade Mass | B23: 113505.68 | C23: [kg]
A24: Tower Mass | B24: 630 | C24: [tons]
... A31: CoE | B31: 75 | C31: [$/MWh]
A33: Version | B33: Revisions | C33: Date | D33: Author | F33: Institution | H33: Comments
A34: 1 | B34: 0 | C34: 43515 | D34: L. Sartori, F. Bellini, A. Croce | F34: PoliMI | H34: Baseline version with DTU controller.

Sheet WTControl
A1: Wind Turbine Control Data
A2: Cp Rated | B2: 0.45018087 | C2: [-] | F2: CTRL | G2: 100
A3: Pitch Rated | B3: 0.21789647 | C3: [deg]
A4: TSR Rated | B4: 7.7314265 | C4: [-]
A5: Omega Rated | B5: 6.7679777 | C5: [rpm]
A6: Torque Rated | B6: 30.020271 | C6: [MNm] | E6: 44.123 | F6: Max torque
A7: Max Tip Speed | B7: 90 | C7: [m/s]
A8: Cut In Wind Speed | B8: 4 | C8: [m/s]
A9: Cut Out Wind Speed | B9: 25 | C9: [m/s]
A10: Wind Speed Rated | B10: 11.559605 | C10: [m/s]
A11: Min Rotor Speed | B11: 1.7564556 | C11: [rpm]
A12: Max Rotor Speed | B12: 7.4447755 | C12: [rpm]
A13: Sample Time Controller | B13: 0.02 | C13: [s]
A15: Look Up Table WT States | I15: Turbulent Power Curve
A16: Wind Speed | B16: Cp | C16: Pitch Angle | D16: TSR | E16: Omega | F16: Torque | G16: Power | I16: Wind Speed | J16: Mech. Power | K16: Electr. Power | L16: Mech. Power Min | M16: Electr. Power Min | N16: Mech. Power Max | O16: Electr. Power Max | P16: Mech. Power Std | Q16: Electr. Power Std
A17: [m/s] | B17: [-] | C17: [deg] | D17: [-] | E17: [rpm] | F17: [MNm] | G17: [MW] | I17: [m/s] | J17: [MW] | K17: [MW] | L17: [MW] | M17: [MW] | N17: [MW] | O17: [MW] | P17: [MW] | Q17: [MW]
A18: 3 | B18: 0.45018087 | C18: 0.21789647 | D18: 7.7314265 | E18: 1.7564556 | F18: 2.0219534 | G18: 0.37190921 | I18: 4 | J18: 0.35673337 | K18: 0.33532937 | L18: -0.045124858 | M18: -0.042417367 | N18: 1.2053236 | O18: 1.1330042 | P18: 0.30207056 | Q18: 0.28394632
A19: 3.1 | B19: 0.45018087 | C19: 0.21789647 | D19: 7.7314265 | E19: 1.8150042 | F19: 2.1589969 | G19: 0.41035361 | I19: 5 | J19: 1.1378371 | K19: 1.0695668 | L19: -0.0081451564 | M19: -0.007656447 | N19: 2.345722 | O19: 2.2049787 | P19: 0.54632127 | Q19: 0.513542
A20: 3.2 | B20: 0.45018087 | C20: 0.21789647 | D20: 7.7314265 | E20: 1.8735527 | F20: 2.3005336 | G20: 0.45136004 | I20: 7 | J20: 4.2897453 | K20: 4.0323605 | L20: 1.6918222 | M20: 1.5903129 | N20: 7.9047226 | O20: 7.4304393 | P20: 1.6084666 | Q20: 1.5119586
A21: 3.3 | B21: 0.45018087 | C21: 0.21789647 | D21: 7.7314265 | E21: 1.9321012 | F21: 2.4465636 | G21: 0.49501116 | I21: 9 | J21: 8.8655334 | K21: 8.3336014 | L21: 5.780951 | M21: 5.434094 | N21: 11.683992 | O21: 10.982952 | P21: 1.833699 | Q21: 1.723677
A22: 3.4 | B22: 0.45018087 | C22: 0.21789647 | D22: 7.7314265 | E22: 1.9906497 | F22: 2.5970868 | G22: 0.54138962 | I22: 11 | J22: 15.935983 | K22: 14.979824 | L22: 11.274165 | M22: 10.597715 | N22: 23.829599 | O22: 22.399823 | P22: 3.7039624 | Q22: 3.4817246
A23: 3.5 | B23: 0.45018087 | C23: 0.21789647 | D23: 7.7314265 | E23: 2.0491982 | F23: 2.7521032 | G23: 0.59057806 | I23: 13 | J23: 21.01544 | K23: 19.754514 | L23: 15.989684 | M23: 15.030303 | N23: 22.952165 | O23: 21.575035 | P23: 1.1193732 | Q23: 1.0522108
A24: 3.6 | B24: 0.45018087 | C24: 0.21789647 | D24: 7.7314265 | E24: 2.1077468 | F24: 2.9116128 | G24: 0.64265912 | I24: 15 | J24: 21.260589 | K24: 19.984953 | L24: 19.333433 | M24: 18.173427 | N24: 24.545127 | O24: 23.07242 | P24: 0.87738597 | Q24: 0.82474281
A25: 3.7 | B25: 0.45018087 | C25: 0.21789647 | D25: 7.7314265 | E25: 2.1662953 | F25: 3.0756157 | G25: 0.69771546 | I25: 17 | J25: 21.254103 | K25: 19.978857 | L25: 18.972946 | M25: 17.83457 | N25: 24.497836 | O25: 23.027966 | P25: 0.78906098 | Q25: 0.74171733
A26: 3.8 | B26: 0.45018087 | C26: 0.21789647 | D26: 7.7314265 | E26: 2.2248438 | F26: 3.2441118 | G26: 0.75582972 | I26: 19 | J26: 21.257886 | K26: 19.982412 | L26: 19.352167 | M26: 18.191037 | N26: 23.404533 | O26: 22.000261 | P26: 0.70655263 | Q26: 0.66415947
A27: 3.9 | B27: 0.45018087 | C27: 0.21789647 | D27: 7.7314265 | E27: 2.2833923 | F27: 3.4171012 | G27: 0.81708454 | I27: 21 | J27: 21.434175 | K27: 20.148125 | L27: 19.253017 | M27: 18.097836 | N27: 24.22793 | O27: 22.774255 | P27: 0.82794768 | Q27: 0.77827082
A28: 4 | B28: 0.45018087 | C28: 0.21789647 | D28: 7.7314265 | E28: 2.3419408 | F28: 3.5945838 | G28: 0.88156258 | I28: 23 | J28: 21.279301 | K28: 20.002543 | L28: 19.534974 | M28: 18.362875 | N28: 23.364082 | O28: 21.962237 | P28: 0.67472261 | Q28: 0.63423926
A29: 4.1 | B29: 0.45018087 | C29: 0.21789647 | D29: 7.7314265 | E29: 2.4004894 | F29: 3.7765596 | G29: 0.94934648 | I29: 25 | J29: 21.442235 | K29: 20.155701 | L29: 19.281487 | M29: 18.124598 | N29: 24.319012 | O29: 22.859872 | P29: 0.81315092 | Q29: 0.76436186
A30: 4.2 | B30: 0.45018087 | C30: 0.21789647 | D30: 7.7314265 | E30: 2.4590379 | F30: 3.9630286 | G30: 1.0205189
A31: 4.3 | B31: 0.45018087 | C31: 0.21789647 | D31: 7.7314265 | E31: 2.5175864 | F31: 4.1539909 | G31: 1.0951624
A32: 4.4 | B32: 0.45018087 | C32: 0.21789647 | D32: 7.7314265 | E32: 2.5761349 | F32: 4.3494463 | G32: 1.1733598
A33: 4.5 | B33: 0.45018087 | C33: 0.21789647 | D33: 7.7314265 | E33: 2.6346834 | F33: 4.5493951 | G33: 1.2551936
A34: 4.6 | B34: 0.45018087 | C34: 0.21789647 | D34: 7.7314265 | E34: 2.693232 | F34: 4.753837 | G34: 1.3407465
A35: 4.7 | B35: 0.45018087 | C35: 0.21789647 | D35: 7.7314265 | E35: 2.7517805 | F35: 4.9627722 | G35: 1.4301011
A36: 4.8 | B36: 0.45018087 | C36: 0.21789647 | D36: 7.7314265 | E36: 2.810329 | F36: 5.1762006 | G36: 1.5233401
A37: 4.9 | B37: 0.45018087 | C37: 0.21789647 | D37: 7.7314265 | E37: 2.8688775 | F37: 5.3941223 | G37: 1.6205462
A38: 5 | B38: 0.45018087 | C38: 0.21789647 | D38: 7.7314265 | E38: 2.9274261 | F38: 5.6165371 | G38: 1.7218019
A39: 5.1 | B39: 0.45018087 | C39: 0.21789647 | D39: 7.7314265 | E39: 2.9859746 | F39: 5.8434452 | G39: 1.82719
A40: 5.2 | B40: 0.45018087 | C40: 0.21789647 | D40: 7.7314265 | E40: 3.0445231 | F40: 6.0748466 | G40: 1.936793
A41: 5.3 | B41: 0.45018087 | C41: 0.21789647 | D41: 7.7314265 | E41: 3.1030716 | F41: 6.3107411 | G41: 2.0506936
...

Sheet BladeExternalGeometry
A1: Eta | B1: Chord | C1: Twist | D1: Pitch Axis | E1: Airfoil Thickness | F1: PreBend | G1: Sweep | H1: AC Axis | I1: LE | J1: TE
A2: [-] | B2: [mm] | C2: [deg] | D2: [% chord] | E2: [%] | F2: [mm] | G2: [mm] | H2: [%] | I2: [mm] | J2: [mm]
A3: 0 | B3: 6505 | C3: 14.5 | D3: 50 | E3: 100 | F3: 0 | G3: 0 | H3: 50 | I3: -3252.5 | J3: 3252.5
A4: 0.01 | B4: 6505 | C4: 14.5 | D4: 50 | E4: 100 | F4: 0 | G4: 0 | H4: 49.981214 | I4: -3252.5 | J4: 3252.5
A5: 0.021276596 | B5: 6505 | C5: 14.5 | D5: 50 | E5: 99.969972 | F5: 0 | G5: 0 | H5: 49.894667 | I5: -3252.5 | J5: 3252.5
A6: 0.025 | B6: 6505 | C6: 14.5 | D6: 50 | E6: 99.941131 | F6: 0 | G6: 0 | H6: 49.86609 | I6: -3252.5 | J6: 3252.5
A7: 0.042553191 | B7: 6505 | C7: 14.5 | D7: 50 | E7: 98.667055 | F7: 0 | G7: 0 | H7: 48.91975 | I7: -3252.5 | J7: 3252.5
A8: 0.05 | B8: 6505 | C8: 14.5 | D8: 50 | E8: 97.668448 | F8: 0 | G8: 0 | H8: 48.518272 | I8: -3252.5 | J8: 3252.5
A9: 0.063829787 | B9: 6507.8432 | C9: 14.5 | D9: 49.907102 | E9: 94.943443 | F9: 0 | G9: 0 | H9: 46.238513 | I9: -3247.8759 | J9: 3259.9673
A10: 0.0834 | B10: 6570.4151 | C10: 14.485059 | D10: 49.775644 | E10: 89.743545 | F10: 0 | G10: 0 | H10: 43.012478 | I10: -3270.4664 | J10: 3299.9487
A11: 0.085106383 | B11: 6587.0912 | C11: 14.476975 | D11: 49.710641 | E11: 89.198173 | F11: 0 | G11: 0 | H11: 42.725184 | I11: -3274.4852 | J11: 3312.6059
A12: 0.1 | B12: 6744.9575 | C12: 14.392158 | D12: 49.143286 | E12: 84.337852 | F12: 0 | G12: 0 | H12: 40.217626 | I12: -3314.6938 | J12: 3430.2638
A13: 0.10638298 | B13: 6837.6657 | C13: 14.320853 | D13: 48.622749 | E13: 82.07095 | F13: 0 | G13: 0 | H13: 39.283725 | I13: -3324.661 | J13: 3513.0046
A14: 0.12765957 | B14: 7210.9558 | C14: 13.894653 | D14: 46.887627 | E14: 74.195299 | F14: 0 | G14: 0 | H14: 36.17072 | I14: -3381.046 | J14: 3829.9098
... A67: 1 | B67: 42.4 | C67: -3.428 | D67: 35 | E67: 24.1 | F67: 0 | G67: 0 | H67: 24.997724 | I67: -14.84 | J67: 27.56

Sheet Airfoils
A1: Airfoil Name | B1: Span Position | C1: Thickness | D1: Reynolds | E1: Chordwise Pitch Position | I1: Airfoil Name | J1: Span Position | K1: Thickness | L1: Reynolds | M1: Chordwise Pitch Position | Q1: Airfoil Name | R1: Span Position | S1: Thickness | T1: Reynolds | U1: Chordwise Pitch Position | Y1: Airfoil Name | Z1: Span Position | AA1: Thickness | AB1: Reynolds | AC1: Chordwise Pitch Position | AG1: Airfoil Name | AH1: Span Position | AI1: Thickness | AJ1: Reynolds | AK1: Chordwise Pitch Position | AO1: Airfoil Name | AP1: Span Position | AQ1: Thickness | AR1: Reynolds | AS1: Chordwise Pitch Position | AW1: Airfoil Name | AX1: Span Position | AY1: Thickness | AZ1: Reynolds | BA1: Chordwise Pitch Position
A2: [-] | B2: [%] | C2: [%] | D2: [-] | E2: [%] | I2: [-] | J2: [%] | K2: [%] | L2: [-] | M2: [%] | Q2: [-] | R2: [%] | S2: [%] | T2: [-] | U2: [%] | Y2: [-] | Z2: [%] | AA2: [%] | AB2: [-] | AC2: [%] | AG2: [-] | AH2: [%] | AI2: [%] | AJ2: [-] | AK2: [%] | AO2: [-] | AP2: [%] | AQ2: [%] | AR2: [-] | AS2: [%] | AW2: [-] | AX2: [%] | AY2: [%] | AZ2: [-] | BA2: [%]
A3: circle | B3: 0 | C3: 100 | D3: 6000000 | E3: 25 | I3: circle | J3: 1.74 | K3: 100 | L3: 6000000 | M3: 25 | Q3: FFA-W3-480 | R3: 20.804587 | S3: 48 | T3: 10000000 | U3: 25 | Y3: FFA-W3-360 | Z3: 29.235895 | AA3: 36 | AB3: 10000000 | AC3: 25 | AG3: FFA-W3-301 | AH3: 38.756972 | AI3: 30.1 | AJ3: 10000000 | AK3: 25 | AO3: FFA-W3-241 | AP3: 71.866463 | AQ3: 24.1 | AR3: 12000000 | AS3: 25 | AW3: FFA-W3-241 | AX3: 100 | AY3: 24.1 | AZ3: 12000000 | BA3: 25
A4: Coordinate X | B4: Coordinate Y | C4: Angle of attack | D4: Cl | E4: Cd | F4: Cm | I4: Coordinate X | J4: Coordinate Y | K4: Angle of attack | L4: Cl | M4: Cd | N4: Cm | Q4: Coordinate X | R4: Coordinate Y | S4: Angle of attack | T4: Cl | U4: Cd | V4: Cm | Y4: Coordinate X | Z4: Coordinate Y | AA4: Angle of attack | AB4: Cl | AC4: Cd | AD4: Cm | AG4: Coordinate X | AH4: Coordinate Y | AI4: Angle of attack | AJ4: Cl | AK4: Cd | AL4: Cm | AO4: Coordinate X | AP4: Coordinate Y | AQ4: Angle of attack | AR4: Cl | AS4: Cd | AT4: Cm | AW4: Coordinate X | AX4: Coordinate Y | AY4: Angle of attack | AZ4: Cl | BA4: Cd | BB4: Cm
A5: [m] | B5: [m] | C5: [deg] | D5: [-] | E5: [-] | F5: [-] | I5: [m] | J5: [m] | K5: [deg] | L5: [-] | M5: [-] | N5: [-] | Q5: [m] | R5: [m] | S5: [deg] | T5: [-] | U5: [-] | V5: [-] | Y5: [m] | Z5: [m] | AA5: [deg] | AB5: [-] | AC5: [-] | AD5: [-] | AG5: [m] | AH5: [m] | AI5: [deg] | AJ5: [-] | AK5: [-] | AL5: [-] | AO5: [m] | AP5: [m] | AQ5: [deg] | AR5: [-] | AS5: [-] | AT5: [-] | AW5: [m] | AX5: [m] | AY5: [deg] | AZ5: [-] | BA5: [-] | BB5: [-]
A6: 1 | B6: 0 | C6: -180 | D6: 0 | E6: 0.6 | F6: 0 | I6: 1 | J6: 0 | K6: -180 | L6: 0 | M6: 0.6 | N6: 0 | Q6: 1 | R6: 0.0200427 | S6: -180 | T6: 0 | U6: 0 | V6: 0 | Y6: 1 | Z6: 0.015032 | AA6: -180 | AB6: 0 | AC6: 0 | AD6: 0 | AG6: 1 | AH6: 0.00937 | AI6: -180 | AJ6: 0 | AK6: 0 | AL6: 0 | AO6: 1 | AP6: 0.00717 | AQ6: -180 | AR6: 0 | AS6: 0 | AT6: 0 | AW6: 1 | AX6: 0.00717 | AY6: -180 | AZ6: 0 | BA6: 0 | BB6: 0
A7: 0.9999 | B7: 0.0087 | C7: -175 | D7: 0 | E7: 0.6 | F7: 0 | I7: 0.9999 | J7: 0.0087 | K7: -175 | L7: 0 | M7: 0.6 | N7: 0 | Q7: 0.983388 | R7: 0.0266293 | S7: -175 | T7: 0.1736 | U7: 0.0099 | V7: 0.0218 | Y7: 0.983388 | Z7: 0.019972 | AA7: -175 | AB7: 0.1736 | AC7: 0.0099 | AD7: 0.0218 | AG7: 0.98338 | AH7: 0.01333 | AI7: -175 | AJ7: 0.1736 | AK7: 0.0099 | AL7: 0.0218 | AO7: 0.978169 | AP7: 0.011572 | AQ7: -175 | AR7: 0.1736 | AS7: 0.01142 | AT7: 0.0218 | AW7: 0.978169 | AX7: 0.011572 | AY7: -175 | AZ7: 0.1736 | BA7: 0.01142 | BB7: 0.0218
A8: 0.9997 | B8: 0.0174 | C8: -170 | D8: 0 | E8: 0.6 | F8: 0 | I8: 0.9997 | J8: 0.0174 | K8: -170 | L8: 0 | M8: 0.6 | N8: 0 | Q8: 0.964566 | R8: 0.0339107 | S8: -170 | T8: 0.342 | U8: 0.0392 | V8: 0.0434 | Y8: 0.964566 | Z8: 0.025433 | AA8: -170 | AB8: 0.342 | AC8: 0.0392 | AD8: 0.0434 | AG8: 0.96457 | AH8: 0.01775 | AI8: -170 | AJ8: 0.342 | AK8: 0.0392 | AL8: 0.0434 | AO8: 0.954424 | AP8: 0.016362 | AQ8: -170 | AR8: 0.342 | AS8: 0.04523 | AT8: 0.0434 | AW8: 0.954424 | AX8: 0.016362 | AY8: -170 | AZ8: 0.342 | BA8: 0.04523 | BB8: 0.0434
A9: 0.9993 | B9: 0.0262 | C9: -165 | D9: 0 | E9: 0.6 | F9: 0 | I9: 0.9993 | J9: 0.0262 | K9: -165 | L9: 0 | M9: 0.6 | N9: 0 | Q9: 0.943643 | R9: 0.041832 | S9: -165 | T9: 0.5 | U9: 0.0871 | V9: 0.0647 | Y9: 0.943643 | Z9: 0.031374 | AA9: -165 | AB9: 0.5 | AC9: 0.0871 | AD9: 0.0647 | AG9: 0.943639 | AH9: 0.02266 | AI9: -165 | AJ9: 0.5 | AK9: 0.0871 | AL9: 0.0647 | AO9: 0.930228 | AP9: 0.021309 | AQ9: -165 | AR9: 0.5 | AS9: 0.1005 | AT9: 0.0647 | AW9: 0.930228 | AX9: 0.021309 | AY9: -165 | AZ9: 0.5 | BA9: 0.1005 | BB9: 0.0647
A10: 0.9988 | B10: 0.0349 | C10: -160 | D10: 0 | E10: 0.6 | F10: 0 | I10: 0.9988 | J10: 0.0349 | K10: -160 | L10: 0 | M10: 0.6 | N10: 0 | Q10: 0.92071 | R10: 0.0504467 | S10: -160 | T10: 0.6428 | U10: 0.1521 | V10: 0.0855 | Y10: 0.92071 | Z10: 0.037835 | AA10: -160 | AB10: 0.6428 | AC10: 0.1521 | AD10: 0.0855 | AG10: 0.920709 | AH10: 0.02812 | AI10: -160 | AJ10: 0.6428 | AK10: 0.1521 | AL10: 0.0855 | AO10: 0.905997 | AP10: 0.026345 | AQ10: -160 | AR10: 0.6428 | AS10: 0.1755 | AT10: 0.0855 | AW10: 0.905997 | AX10: 0.026345 | AY10: -160 | AZ10: 0.6428 | BA10: 0.1755 | BB10: 0.0855
A11: 0.9981 | B11: 0.0436 | C11: -155 | D11: 0 | E11: 0.6 | F11: 0 | I11: 0.9981 | J11: 0.0436 | K11: -155 | L11: 0 | M11: 0.6 | N11: 0 | Q11: 0.895877 | R11: 0.05986 | S11: -155 | T11: 0.766 | U11: 0.2322 | V11: 0.1057 | Y11: 0.895877 | Z11: 0.044895 | AA11: -155 | AB11: 0.766 | AC11: 0.2322 | AD11: 0.1057 | AG11: 0.895879 | AH11: 0.03417 | AI11: -155 | AJ11: 0.766 | AK11: 0.2322 | AL11: 0.1057 | AO11: 0.881745 | AP11: 0.031453 | AQ11: -155 | AR11: 0.766 | AS11: 0.26792 | AT11: 0.1057 | AW11: 0.881745 | AX11: 0.031453 | AY11: -155 | AZ11: 0.766 | BA11: 0.26792 | BB11: 0.1057
A12: 0.9973 | B12: 0.0523 | C12: -150 | D12: 0 | E12: 0.6 | F12: 0 | I12: 0.9973 | J12: 0.0523 | K12: -150 | L12: 0 | M12: 0.6 | N12: 0 | Q12: 0.869274 | R12: 0.0700213 | S12: -150 | T12: 0.866 | U12: 0.325 | V12: 0.125 | Y12: 0.869274 | Z12: 0.052516 | AA12: -150 | AB12: 0.866 | AC12: 0.325 | AD12: 0.125 | AG12: 0.869269 | AH12: 0.04074 | AI12: -150 | AJ12: 0.866 | AK12: 0.325 | AL12: 0.125 | AO12: 0.857493 | AP12: 0.036624 | AQ12: -150 | AR12: 0.866 | AS12: 0.375 | AT12: 0.125 | AW12: 0.857493 | AX12: 0.036624 | AY12: -150 | AZ12: 0.866 | BA12: 0.375 | BB12: 0.125
A13: 0.9963 | B13: 0.0609 | C13: -145 | D13: 0 | E13: 0.6 | F13: 0 | I13: 0.9963 | J13: 0.0609 | K13: -145 | L13: 0 | M13: 0.6 | N13: 0 | Q13: 0.841011 | R13: 0.0808493 | S13: -145 | T13: 0.9397 | U13: 0.4277 | V13: 0.1434 | Y13: 0.841011 | Z13: 0.060637 | AA13: -145 | AB13: 0.9397 | AC13: 0.4277 | AD13: 0.1434 | AG13: 0.841008 | AH13: 0.0478 | AI13: -145 | AJ13: 0.9397 | AK13: 0.4277 | AL13: 0.1434 | AO13: 0.833242 | AP13: 0.041848 | AQ13: -145 | AR13: 0.9397 | AS13: 0.4935 | AT13: 0.1434 | AW13: 0.833242 | AX13: 0.041848 | AY13: -145 | AZ13: 0.9397 | BA13: 0.4935 | BB13: 0.1434
A14: 0.9951 | B14: 0.0696 | C14: -140 | D14: 0 | E14: 0.6 | F14: 0 | I14: 0.9951 | J14: 0.0696 | K14: -140 | L14: 0 | M14: 0.6 | N14: 0 | Q14: 0.811237 | R14: 0.0922773 | S14: -140 | T14: 0.9848 | U14: 0.5371 | V14: 0.1607 | Y14: 0.811237 | Z14: 0.069208 | AA14: -140 | AB14: 0.9848 | AC14: 0.5371 | AD14: 0.1607 | AG14: 0.811238 | AH14: 0.055281 | AI14: -140 | AJ14: 0.9848 | AK14: 0.5371 | AL14: 0.1607 | AO14: 0.808999 | AP14: 0.047121 | AQ14: -140 | AR14: 0.9848 | AS14: 0.61973 | AT14: 0.1607 | AW14: 0.808999 | AX14: 0.047121 | AY14: -140 | AZ14: 0.9848 | BA14: 0.61973 | BB14: 0.1607
A15: 0.9938 | B15: 0.0782 | C15: -135 | D15: 0 | E15: 0.6 | F15: 0 | I15: 0.9938 | J15: 0.0782 | K15: -135 | L15: 0 | M15: 0.6 | N15: 0 | Q15: 0.780084 | R15: 0.104212 | S15: -135 | T15: 1 | U15: 0.65 | V15: 0.1768 | Y15: 0.780084 | Z15: 0.078159 | AA15: -135 | AB15: 1 | AC15: 0.65 | AD15: 0.1768 | AG15: 0.780088 | AH15: 0.063091 | AI15: -135 | AJ15: 1 | AK15: 0.65 | AL15: 0.1768 | AO15: 0.784743 | AP15: 0.052434 | AQ15: -135 | AR15: 1 | AS15: 0.75 | AT15: 0.1768 | AW15: 0.784743 | AX15: 0.052434 | AY15: -135 | AZ15: 1 | BA15: 0.75 | BB15: 0.1768
A16: 0.9924 | B16: 0.0868 | C16: -130 | D16: 0 | E16: 0.6 | F16: 0 | I16: 0.9924 | J16: 0.0868 | K16: -130 | L16: 0 | M16: 0.6 | N16: 0 | Q16: 0.74771 | R16: 0.116547 | S16: -130 | T16: 0.9848 | U16: 0.7629 | V16: 0.1915 | Y16: 0.74771 | Z16: 0.08741 | AA16: -130 | AB16: 0.9848 | AC16: 0.7629 | AD16: 0.1915 | AG16: 0.747717 | AH16: 0.071161 | AI16: -130 | AJ16: 0.9848 | AK16: 0.7629 | AL16: 0.1915 | AO16: 0.760466 | AP16: 0.057767 | AQ16: -130 | AR16: 0.9848 | AS16: 0.88027 | AT16: 0.1915 | AW16: 0.760466 | AX16: 0.057767 | AY16: -130 | AZ16: 0.9848 | BA16: 0.88027 | BB16: 0.1915
A17: 0.9908 | B17: 0.0954 | C17: -125 | D17: 0 | E17: 0.6 | F17: 0 | I17: 0.9908 | J17: 0.0954 | K17: -125 | L17: 0 | M17: 0.6 | N17: 0 | Q17: 0.714276 | R17: 0.129176 | S17: -125 | T17: 0.9397 | U17: 0.8723 | V17: 0.2048 | Y17: 0.714276 | Z17: 0.096882 | AA17: -125 | AB17: 0.9397 | AC17: 0.8723 | AD17: 0.2048 | AG17: 0.714277 | AH17: 0.079391 | AI17: -125 | AJ17: 0.9397 | AK17: 0.8723 | AL17: 0.2048 | AO17: 0.736173 | AP17: 0.063102 | AQ17: -125 | AR17: 0.9397 | AS17: 1.0065 | AT17: 0.2048 | AW17: 0.736173 | AX17: 0.063102 | AY17: -125 | AZ17: 0.9397 | BA17: 1.0065 | BB17: 0.2048
... A84: 0.604 | B84: 0.4891 | C84: 3 | D84: 0 | E84: 0.6 | F84: 0 | I84: 0.604 | J84: 0.4891 | K84: 3 | L84: 0 | M84: 0.6 | N84: 0 | Q84: 1 | R84: -0.018576 | S84: 3 | T84: 0.72105 | U84: 0.03295 | V84: -0.0694 | Y84: 1 | Z84: -0.013932 | AA84: 3 | AB84: 0.9725 | AC84: 0.0192 | AD84: -0.14195 | AG84: 1 | AH84: -0.00891 | AI84: 3 | AJ84: 0.69345 | AK84: 0.0122 | AL84: -0.0989 | AO84: 0.558881 | AP84: -0.073505 | AQ84: 3 | AR84: 0.6651 | AS84: 0.01005 | AT84: -0.08965 | AW84: 0.558881 | AX84: -0.073505 | AY84: 3 | AZ84: 0.6651 | BA84: 0.01005 | BB84: -0.08965
A85: 0.5954 | B85: 0.4908 | C85: 3.5 | D85: 0 | E85: 0.6 | F85: 0 | I85: 0.5954 | J85: 0.4908 | K85: 3.5 | L85: 0 | M85: 0.6 | N85: 0 | S85: 3.5 | T85: 0.798975 | U85: 0.033625 | V85: -0.0794 | AA85: 3.5 | AB85: 1.0467 | AC85: 0.0194 | AD85: -0.146475 | AI85: 3.5 | AJ85: 0.756675 | AK85: 0.01235 | AL85: -0.10065 | AO85: 0.582236 | AP85: -0.066021 | AQ85: 3.5 | AR85: 0.7259 | AS85: 0.010175 | AT85: -0.090825 | AW85: 0.582236 | AX85: -0.066021 | AY85: 3.5 | AZ85: 0.7259 | BA85: 0.010175 | BB85: -0.090825
A86: 0.5868 | B86: 0.4924 | C86: 4 | D86: 0 | E86: 0.6 | F86: 0 | I86: 0.5868 | J86: 0.4924 | K86: 4 | L86: 0 | M86: 0.6 | N86: 0 | S86: 4 | T86: 0.8769 | U86: 0.0343 | V86: -0.0894 | AA86: 4 | AB86: 1.1209 | AC86: 0.0196 | AD86: -0.151 | AI86: 4 | AJ86: 0.8199 | AK86: 0.0125 | AL86: -0.1024 | AO86: 0.605662 | AP86: -0.058295 | AQ86: 4 | AR86: 0.7867 | AS86: 0.0103 | AT86: -0.092 | AW86: 0.605662 | AX86: -0.058295 | AY86: 4 | AZ86: 0.7867 | BA86: 0.0103 | BB86: -0.092
A87: 0.5782 | B87: 0.4938 | C87: 4.5 | D87: 0 | E87: 0.6 | F87: 0 | I87: 0.5782 | J87: 0.4938 | K87: 4.5 | L87: 0 | M87: 0.6 | N87: 0 | S87: 4.5 | T87: 0.9183 | U87: 0.037 | V87: -0.09497 | AA87: 4.5 | AB87: 1.1881 | AC87: 0.020025 | AD87: -0.153995 | AI87: 4.5 | AJ87: 0.880275 | AK87: 0.012775 | AL87: -0.103575 | AO87: 0.629144 | AP87: -0.050467 | AQ87: 4.5 | AR87: 0.845725 | AS87: 0.010525 | AT87: -0.0929 | AW87: 0.629144 | AX87: -0.050467 | AY87: 4.5 | AZ87: 0.845725 | BA87: 0.010525 | BB87: -0.0929
A88: 0.5696 | B88: 0.4951 | C88: 5 | D88: 0 | E88: 0.6 | F88: 0 | I88: 0.5696 | J88: 0.4951 | K88: 5 | L88: 0 | M88: 0.6 | N88: 0 | S88: 5 | T88: 0.9597 | U88: 0.0397 | V88: -0.10054 | AA88: 5 | AB88: 1.2553 | AC88: 0.02045 | AD88: -0.15699 | AI88: 5 | AJ88: 0.94065 | AK88: 0.01305 | AL88: -0.10475 | AO88: 0.652569 | AP88: -0.04272 | AQ88: 5 | AR88: 0.90475 | AS88: 0.01075 | AT88: -0.0938 | AW88: 0.652569 | AX88: -0.04272 | AY88: 5 | AZ88: 0.90475 | BA88: 0.01075 | BB88: -0.0938
A89: 0.5609 | B89: 0.4963 | C89: 5.5 | D89: 0 | E89: 0.6 | F89: 0 | I89: 0.5609 | J89: 0.4963 | K89: 5.5 | L89: 0 | M89: 0.6 | N89: 0 | S89: 5.5 | T89: 1.0011 | U89: 0.0424 | V89: -0.10611 | AA89: 5.5 | AB89: 1.3225 | AC89: 0.020875 | AD89: -0.159985 | AI89: 5.5 | AJ89: 1.001025 | AK89: 0.013325 | AL89: -0.105925 | AO89: 0.67591 | AP89: -0.035205 | AQ89: 5.5 | AR89: 0.963775 | AS89: 0.010975 | AT89: -0.0947 | AW89: 0.67591 | AX89: -0.035205 | AY89: 5.5 | AZ89: 0.963775 | BA89: 0.010975 | BB89: -0.0947
A90: 0.5523 | B90: 0.4973 | C90: 6 | D90: 0 | E90: 0.6 | F90: 0 | I90: 0.5523 | J90: 0.4973 | K90: 6 | L90: 0 | M90: 0.6 | N90: 0 | S90: 6 | T90: 1.0425 | U90: 0.0451 | V90: -0.11168 | AA90: 6 | AB90: 1.3897 | AC90: 0.0213 | AD90: -0.16298 | AI90: 6 | AJ90: 1.0614 | AK90: 0.0136 | AL90: -0.1071 | AO90: 0.699179 | AP90: -0.02806 | AQ90: 6 | AR90: 1.0228 | AS90: 0.0112 | AT90: -0.0956 | AW90: 0.699179 | AX90: -0.02806 | AY90: 6 | AZ90: 1.0228 | BA90: 0.0112 | BB90: -0.0956
A91: 0.5436 | B91: 0.4981 | C91: 6.5 | D91: 0 | E91: 0.6 | F91: 0 | I91: 0.5436 | J91: 0.4981 | K91: 6.5 | L91: 0 | M91: 0.6 | N91: 0 | S91: 6.5 | T91: 1.01905 | U91: 0.051325 | V91: -0.11397 | AA91: 6.5 | AB91: 1.448625 | AC91: 0.021975 | AD91: -0.164505 | AI91: 6.5 | AJ91: 1.1179 | AK91: 0.014 | AL91: -0.107675 | AO91: 0.722432 | AP91: -0.021408 | AQ91: 6.5 | AR91: 1.07895 | AS91: 0.01155 | AT91: -0.096075 | AW91: 0.722432 | AX91: -0.021408 | AY91: 6.5 | AZ91: 1.07895 | BA91: 0.01155 | BB91: -0.096075
A92: 0.5349 | B92: 0.4988 | C92: 7 | D92: 0 | E92: 0.6 | F92: 0 | I92: 0.5349 | J92: 0.4988 | K92: 7 | L92: 0 | M92: 0.6 | N92: 0 | S92: 7 | T92: 0.9956 | U92: 0.05755 | V92: -0.11626 | AA92: 7 | AB92: 1.50755 | AC92: 0.02265 | AD92: -0.16603 | AI92: 7 | AJ92: 1.1744 | AK92: 0.0144 | AL92: -0.10825 | AO92: 0.745723 | AP92: -0.015321 | AQ92: 7 | AR92: 1.1351 | AS92: 0.0119 | AT92: -0.09655 | AW92: 0.745723 | AX92: -0.015321 | AY92: 7 | AZ92: 1.1351 | BA92: 0.0119 | BB92: -0.09655
A93: 0.5262 | B93: 0.4993 | C93: 7.5 | D93: 0 | E93: 0.6 | F93: 0 | I93: 0.5262 | J93: 0.4993 | K93: 7.5 | L93: 0 | M93: 0.6 | N93: 0 | S93: 7.5 | T93: 0.97215 | U93: 0.063775 | V93: -0.11855 | AA93: 7.5 | AB93: 1.566475 | AC93: 0.023325 | AD93: -0.167555 | AI93: 7.5 | AJ93: 1.2309 | AK93: 0.0148 | AL93: -0.108825 | AO93: 0.769017 | AP93: -0.009891 | AQ93: 7.5 | AR93: 1.19125 | AS93: 0.01225 | AT93: -0.097025 | AW93: 0.769017 | AX93: -0.009891 | AY93: 7.5 | AZ93: 1.19125 | BA93: 0.01225 | BB93: -0.097025
A94: 0.5174 | B94: 0.4997 | C94: 8 | D94: 0 | E94: 0.6 | F94: 0 | I94: 0.5174 | J94: 0.4997 | K94: 8 | L94: 0 | M94: 0.6 | N94: 0 | S94: 8 | T94: 0.9487 | U94: 0.07 | V94: -0.12084 | AA94: 8 | AB94: 1.6254 | AC94: 0.024 | AD94: -0.16908 | AI94: 8 | AJ94: 1.2874 | AK94: 0.0152 | AL94: -0.1094 | AO94: 0.792279 | AP94: -0.005241 | AQ94: 8 | AR94: 1.2474 | AS94: 0.0126 | AT94: -0.0975 | AW94: 0.792279 | AX94: -0.005241 | AY94: 8 | AZ94: 1.2474 | BA94: 0.0126 | BB94: -0.0975
A95: 0.5087 | B95: 0.4999 | C95: 8.5 | D95: 0 | E95: 0.6 | F95: 0 | I95: 0.5087 | J95: 0.4999 | K95: 8.5 | L95: 0 | M95: 0.6 | N95: 0 | S95: 8.5 | T95: 0.938725 | U95: 0.07465 | V95: -0.12503 | AA95: 8.5 | AB95: 1.671775 | AC95: 0.024975 | AD95: -0.16889 | AI95: 8.5 | AJ95: 1.33655 | AK95: 0.0159 | AL95: -0.10904 | AO95: 0.815582 | AP95: -0.001458 | AQ95: 8.5 | AR95: 1.299925 | AS95: 0.0131 | AT95: -0.09753 | AW95: 0.815582 | AX95: -0.001458 | AY95: 8.5 | AZ95: 1.299925 | BA95: 0.0131 | BB95: -0.09753
A96: 0.5 | B96: 0.5 | C96: 9 | D96: 0 | E96: 0.6 | F96: 0 | I96: 0.5 | J96: 0.5 | K96: 9 | L96: 0 | M96: 0.6 | N96: 0 | S96: 9 | T96: 0.92875 | U96: 0.0793 | V96: -0.12922 | AA96: 9 | AB96: 1.71815 | AC96: 0.02595 | AD96: -0.1687 | AI96: 9 | AJ96: 1.3857 | AK96: 0.0166 | AL96: -0.10868 | AO96: 0.83903 | AP96: 0.001479 | AQ96: 9 | AR96: 1.35245 | AS96: 0.0136 | AT96: -0.09756 | AW96: 0.83903 | AX96: 0.001479 | AY96: 9 | AZ96: 1.35245 | BA96: 0.0136 | BB96: -0.09756
... A103: 0.4391 | B103: 0.4963 | C103: 12.5 | D103: 0 | E103: 0.6 | F103: 0 | I103: 0.4391 | J103: 0.4963 | K103: 12.5 | L103: 0 | M103: 0.6 | N103: 0 | S103: 12.5 | T103: 1.010325 | U103: 0.101225 | V103: -0.16515 | AA103: 12.5 | AB103: 1.84815 | AC103: 0.046375 | AD103: -0.1578 | AI103: 12.5 | AJ103: 1.662275 | AK103: 0.024375 | AL103: -0.10073 | AO103: 1 | AP103: -0.001548 | AQ103: 12.5 | AR103: 1.67725 | AS103: 0.0188 | AT103: -0.09348 | AW103: 1 | AX103: -0.001548 | AY103: 12.5 | AZ103: 1.67725 | BA103: 0.0188 | BB103: -0.09348
A104: 0.4304 | B104: 0.4951 | C104: 13 | D104: 0 | E104: 0.6 | F104: 0 | I104: 0.4304 | J104: 0.4951 | K104: 13 | L104: 0 | M104: 0.6 | N104: 0 | S104: 13 | T104: 1.04455 | U104: 0.10315 | V104: -0.17088 | AA104: 13 | AB104: 1.8374 | AC104: 0.05625 | AD104: -0.15712 | AI104: 13 | AJ104: 1.68575 | AK104: 0.02635 | AL104: -0.0989 | AQ104: 13 | AR104: 1.7123 | AS104: 0.0201 | AT104: -0.09208 | AY104: 13 | AZ104: 1.7123 | BA104: 0.0201 | BB104: -0.09208
A105: 0.4218 | B105: 0.4938 | C105: 13.5 | D105: 0 | E105: 0.6 | F105: 0 | I105: 0.4218 | J105: 0.4938 | K105: 13.5 | L105: 0 | M105: 0.6 | N105: 0 | S105: 13.5 | T105: 1.078775 | U105: 0.105075 | V105: -0.17661 | AA105: 13.5 | AB105: 1.82665 | AC105: 0.066125 | AD105: -0.15644 | AI105: 13.5 | AJ105: 1.709225 | AK105: 0.028325 | AL105: -0.09707 | AQ105: 13.5 | AR105: 1.74735 | AS105: 0.0214 | AT105: -0.09068 | AY105: 13.5 | AZ105: 1.74735 | BA105: 0.0214 | BB105: -0.09068
A106: 0.4132 | B106: 0.4924 | C106: 14 | D106: 0 | E106: 0.6 | F106: 0 | I106: 0.4132 | J106: 0.4924 | K106: 14 | L106: 0 | M106: 0.6 | N106: 0 | S106: 14 | T106: 1.113 | U106: 0.107 | V106: -0.18234 | AA106: 14 | AB106: 1.8159 | AC106: 0.076 | AD106: -0.15576 | AI106: 14 | AJ106: 1.7327 | AK106: 0.0303 | AL106: -0.09524 | AQ106: 14 | AR106: 1.7824 | AS106: 0.0227 | AT106: -0.08928 | AY106: 14 | AZ106: 1.7824 | BA106: 0.0227 | BB106: -0.08928
A107: 0.4046 | B107: 0.4908 | C107: 15 | D107: 0 | E107: 0.6 | F107: 0 | I107: 0.4046 | J107: 0.4908 | K107: 15 | L107: 0 | M107: 0.6 | N107: 0 | S107: 15 | T107: 1.20975 | U107: 0.11165 | V107: -0.19449 | AA107: 15 | AB107: 1.79725 | AC107: 0.09625 | AD107: -0.16136 | AI107: 15 | AJ107: 1.72345 | AK107: 0.0421 | AL107: -0.09314 | AQ107: 15 | AR107: 1.79955 | AS107: 0.0292 | AT107: -0.08559 | AY107: 15 | AZ107: 1.79955 | BA107: 0.0292 | BB107: -0.08559
A108: 0.396 | B108: 0.4891 | C108: 16 | D108: 0 | E108: 0.6 | F108: 0 | I108: 0.396 | J108: 0.4891 | K108: 16 | L108: 0 | M108: 0.6 | N108: 0 | S108: 16 | T108: 1.3065 | U108: 0.1163 | V108: -0.20664 | AA108: 16 | AB108: 1.7786 | AC108: 0.1165 | AD108: -0.16696 | AI108: 16 | AJ108: 1.7142 | AK108: 0.0539 | AL108: -0.09104 | AQ108: 16 | AR108: 1.8167 | AS108: 0.0357 | AT108: -0.0819 | AY108: 16 | AZ108: 1.8167 | BA108: 0.0357 | BB108: -0.0819
A109: 0.3875 | B109: 0.4872 | C109: 17 | D109: 0 | E109: 0.6 | F109: 0 | I109: 0.3875 | J109: 0.4872 | K109: 17 | L109: 0 | M109: 0.6 | N109: 0 | S109: 17 | T109: 1.42395 | U109: 0.124 | V109: -0.21907 | AA109: 17 | AB109: 1.7673 | AC109: 0.1368 | AD109: -0.17395 | AI109: 17 | AJ109: 1.6985 | AK109: 0.07465 | AL109: -0.09449 | AQ109: 17 | AR109: 1.7965 | AS109: 0.0503 | AT109: -0.0806 | AY109: 17 | AZ109: 1.7965 | BA109: 0.0503 | BB109: -0.0806
A110: 0.379 | B110: 0.4851 | C110: 18 | D110: 0 | E110: 0.6 | F110: 0 | I110: 0.379 | J110: 0.4851 | K110: 18 | L110: 0 | M110: 0.6 | N110: 0 | S110: 18 | T110: 1.5414 | U110: 0.1317 | V110: -0.2315 | AA110: 18 | AB110: 1.756 | AC110: 0.1571 | AD110: -0.18094 | AI110: 18 | AJ110: 1.6828 | AK110: 0.0954 | AL110: -0.09794 | AQ110: 18 | AR110: 1.7763 | AS110: 0.0649 | AT110: -0.0793 | AY110: 18 | AZ110: 1.7763 | BA110: 0.0649 | BB110: -0.0793
A111: 0.3706 | B111: 0.483 | C111: 19 | D111: 0 | E111: 0.6 | F111: 0 | I111: 0.3706 | J111: 0.483 | K111: 19 | L111: 0 | M111: 0.6 | N111: 0 | S111: 19 | T111: 1.67315 | U111: 0.14435 | V111: -0.24406 | AA111: 19 | AB111: 1.7595 | AC111: 0.1817 | AD111: -0.18846 | AI111: 19 | AJ111: 1.66975 | AK111: 0.11945 | AL111: -0.10412 | AQ111: 19 | AR111: 1.71855 | AS111: 0.0832 | AT111: -0.08217 | AY111: 19 | AZ111: 1.71855 | BA111: 0.0832 | BB111: -0.08217
A112: 0.3622 | B112: 0.4806 | C112: 20 | D112: 0 | E112: 0.6 | F112: 0 | I112: 0.3622 | J112: 0.4806 | K112: 20 | L112: 0 | M112: 0.6 | N112: 0 | S112: 20 | T112: 1.8049 | U112: 0.157 | V112: -0.25662 | AA112: 20 | AB112: 1.763 | AC112: 0.2063 | AD112: -0.19598 | AI112: 20 | AJ112: 1.6567 | AK112: 0.1435 | AL112: -0.1103 | AQ112: 20 | AR112: 1.6608 | AS112: 0.1015 | AT112: -0.08504 | AY112: 20 | AZ112: 1.6608 | BA112: 0.1015 | BB112: -0.08504
...

Sheet BladeTopology
A1: LE | B1: TE | C1: Chord Lenght | D1: Eta | E1: Blade Lenght (Position) | F1: Sectional Topology | G1: Position of Front Web | H1: Position of Rear Web | I1: Position Spar Cap towards Leading Edge on Suction Side | J1: Position Spar Cap towards Trailing Edge on Suction Side | K1: Width of the Spar Cap on Suction Side | L1: Position Spar Cap towards Leading Edge on Pressure Side | M1: Position Spar Cap towards Trailing Edge on Pressure Side | N1: Width of the Spar Cap on Pressure Side | O1: Extension of the Reinforcement Strip at Leading Edge | P1: Extension of the Reinforcement Strip at Trailing Edge | Q1: Position of the Third Web | R1: Angle of the Webs in the Root Reference Frame | S1: Position of Trailing Edge Add On | T1: Position of Extra Web inside the Trailing Edge Addon | U1: Position of Reinforcement inside the Cylinder | W1: Position of Front Web | X1: Position of Rear Web | Y1: Position Spar Cap towards Leading Edge on Suction Side - Start Spar Cap SS | Z1: Position Spar Cap towards Trailing Edge on Suction Side - End Spar Cap SS | AA1: Position Spar Cap towards Leading Edge on Pressure Side - Start Spar Cap PS | AB1: Position Spar Cap towards Trailing Edge on Pressure Side - End Spar Cap PS | AC1: Extension of the Reinforcement Strip at Leading Edge - Note: Use on SS and PS | AD1: Extension of the Reinforcement Strip at Trailing Edge - Note: Use on SS and PS | AE1: Position of the Third Web | AG1: OUTPUT: | AH1: Section | AI1: Blade Lenght (Position) | AJ1: Position of Front Web | AK1: Position of Rear Web | AL1: Position Spar Cap towards Leading Edge on Suction Side - Start Spar Cap SS | AM1: Position Spar Cap towards Trailing Edge on Suction Side - End Spar Cap SS | AN1: Position Spar Cap towards Leading Edge on Pressure Side - Start Spar Cap PS | AO1: Position Spar Cap towards Trailing Edge on Pressure Side - End Spar Cap PS | AP1: Extension of the Reinforcement Strip at Leading Edge - Note: Use on SS and PS | AQ1: Extension of the Reinforcement Strip at Trailing Edge - Note: Use on SS and PS | AR1: Position of the Third Web | AU1: Blade Position | AV1: For Ansys | AW1: For Ansys | AX1: Blade Reference Line | AY1: Offset | AZ1: Position of shear web front | BA1: Position of shear web rear | BB1: For Ansys | BC1: For Ansys | BE1: For Ansys | BF1: Thickness | BH1: For Ansys | BI1: Twist | BL1: Korrekturfaktor | BM1: For Ansys | BN1: For Ansys
A2: [mm] | B2: [mm] | C2: [mm] | D2: [-] | E2: [m] | F2: [-] | G2: [mm] | H2: [mm] | I2: [mm] | J2: [mm] | K2: [mm] | L2: [mm] | M2: [mm] | N2: [mm] | O2: [mm] | P2: [mm] | Q2: [mm] | R2: [mm] | S2: [mm] | T2: [mm] | U2: [mm] | W2: [%] | X2: [%] | Y2: [%] | Z2: [%] | AA2: [%] | AB2: [%] | AC2: [%] | AD2: [%] | AE2: [%] | AH2: [-] | AI2: [m] | AJ2: [%] | AK2: [%] | AL2: [%] | AM2: [%] | AN2: [%] | AO2: [%] | AP2: [%] | AQ2: [%] | AR2: [%] | AU2: z-direction | AV2: z-direction min | AW2: z-direction max | AX2: y-Direction | AY2: x-direction | AZ2: x-direction | BA2: x-direction | BB2: x-direction min | BC2: x-direction max | BE2: y-direction max | BH2: y-direction min | BM2: x-direction min | BN2: x-direction max | BQ2: Number | BR2: Blade Position | BS2: Jet_X1 | BT2: Jet_X2 | BU2: Jet_Y1 | BV2: Jet_Y2 | BW2: Jet_Z1 | BX2: Jet_Z2 | BY2: F_x | BZ2: F_y | CA2: F_z | CB2: M_x | CC2: M_y | CD2: M_z
A3: -3252.5 | B3: 3252.5 | C3: =(A3*-1)+B3 -> 6505 | D3: 0 | E3: =D3*122.1399685 -> 0 | F3: 1 | G3: -3252.5 | H3: 3252.5 | I3: -3252.5 | J3: 3252.5 | K3: 6505 | L3: -3252.5 | M3: 3252.5 | N3: 6505 | O3: 0 | P3: 0 | Q3: 0 | R3: 0 | S3: 0 | T3: 0 | U3: 0 | W3: =(((A3-G3)*-1)/(C3/100)) -> 0 | X3: =(((A3*-1)+H3)/(C3/100)) -> 100 | Y3: =(((A3-I3)*-1)/(C3/100)) -> 0 | Z3: =(((A3*-1)+J3)/(C3/100)) -> 100 | AA3: =(((A3-L3)*-1)/(C3/100)) -> 0 | AB3: =(((A3*-1)+M3)/(C3/100)) -> 100 | AC3: =(O3/(C3/100)) -> 0 | AD3: =((C3-P3)/(C3/100)) -> 100 | AE3: =(((A3*-1)+Q3)/(C3/100)) -> 50 | AH3: 1 | AI3: 0 | AJ3: =_xll.SRS1Splines.Functions25.Linear_Interp($E$3:$E$67,$W$3:$W$67,AI3) -> 0 | AK3: =_xll.SRS1Splines.Functions25.Linear_Interp($E$3:$E$67,$X$3:$X$67,AI3) -> 100 | AL3: =_xll.SRS1Splines.Functions25.Linear_Interp($E$3:$E$67,$Y$3:$Y$67,AI3) -> 0 | AM3: =_xll.SRS1Splines.Functions25.Linear_Interp($E$3:$E$67,$Z$3:$Z$67,AI3) -> 100 | AN3: =_xll.SRS1Splines.Functions25.Linear_Interp($E$3:$E$67,$AA$3:$AA$67,AI3) -> 0 | AO3: =_xll.SRS1Splines.Functions25.Linear_Interp($E$3:$E$67,$AB$3:$AB$67,AI3) -> 100 | AP3: =_xll.SRS1Splines.Functions25.Linear_Interp($E$3:$E$67,$AC$3:$AC$67,AI3) -> 0 | AQ3: =_xll.SRS1Splines.Functions25.Linear_Interp($E$3:$E$67,$AD$3:$AD$67,AI3) -> 100 | AR3: =_xll.SRS1Splines.Functions25.Linear_Interp($E$3:$E$67,$AE$3:$AE$67,AI3) -> 50 | AU3: =E3 -> 0 | AX3: 0 | AY3: 0.50084487 | AZ3: =(W3/100)*(C3/1000) -> 0 | BA3: =(X3/100)*(C3/1000) -> 6.505 | BB3: =((AY3*(C3/1000))-AZ3)*-1 -> -3.2579959 | BC3: =BA3-(AY3*(C3/1000)) -> 3.2470041 | BD3: =AX3 -> 0 | BE3: 10 | BF3: 6.5049581 | BG3: =BF3/2 -> 3.2524791 | BH3: =(BG3*0.85)+BD3 -> 2.7646072 | BI3: 14.5 | BJ3: =TAN(RADIANS(BI3))*BG3 -> 0.84114828 | BK3: =SIN(RADIANS(BI3))*BG3 -> 0.81435572 | BL3: =0.02*BF3 -> 0.13009916 | BM3: =BB3-BJ3+BL3 -> -3.969045 | BN3: =BC3-BJ3-BL3 -> 2.2757567 | BO3: =BB3-BK3 -> -4.0723516 | BP3: =BC3-BK3 -> 2.4326484 | BQ3: 1 | BR3: 0 | BS3: =BM3 -> -3.969045 | BT3: =BN3 -> 2.2757567 | BU3: =BH3 -> 2.7646072 | BV3: 10 | BW3: =AV3 -> 0 | BX3: =AW3 -> 0 | BY3: 0 | BZ3: =BR3/10 -> 0 | CA3: 0 | CB3: 0 | CC3: 0 | CD3: 0 | CF3: 1 | CG3: =(AY3*(C3/1000))*-1 -> -3.2579959 | CH3: =CG3+(C3/1000) -> 3.2470041 | CI3: =CG3-BJ3 -> -4.0991441 | CJ3: =CH3-BJ3 -> 2.4058559 | CK3: =0.75*CG3 -> -2.4434969 | CL3: =0.75*CH3 -> 2.4352531 | CN3: =AU3-0.5 -> -0.5 | CO3: =AU3+0.5 -> 0.5
A4: -3252.5 | B4: 3252.5 | C4: =(A4*-1)+B4 -> 6505 | D4: 0.01 | E4: =D4*122.1399685 -> 1.2213997 | F4: 1 | G4: -3252.5 | H4: 3252.5 | I4: -3252.5 | J4: 3252.5 | K4: 6505 | L4: -3252.5 | M4: 3252.5 | N4: 6505 | O4: 0 | P4: 0 | Q4: 0 | R4: 0 | S4: 0 | T4: 0 | U4: 0 | W4: =(((A4-G4)*-1)/(C4/100)) -> 0 | X4: =(((A4*-1)+H4)/(C4/100)) -> 100 | Y4: =(((A4-I4)*-1)/(C4/100)) -> 0 | Z4: =(((A4*-1)+J4)/(C4/100)) -> 100 | AA4: =(((A4-L4)*-1)/(C4/100)) -> 0 | AB4: =(((A4*-1)+M4)/(C4/100)) -> 100 | AC4: =(O4/(C4/100)) -> 0 | AD4: =((C4-P4)/(C4/100)) -> 100 | AE4: =(((A4*-1)+Q4)/(C4/100)) -> 50 | AH4: 2 | AI4: 2.8496403 | AJ4: =_xll.SRS1Splines.Functions25.Linear_Interp($E$3:$E$67,$W$3:$W$67,AI4) -> 12.4113 | AK4: =_xll.SRS1Splines.Functions25.Linear_Interp($E$3:$E$67,$X$3:$X$67,AI4) -> 88.357201 | AL4: =_xll.SRS1Splines.Functions25.Linear_Interp($E$3:$E$67,$Y$3:$Y$67,AI4) -> 11.540332 | AM4: =_xll.SRS1Splines.Functions25.Linear_Interp($E$3:$E$67,$Z$3:$Z$67,AI4) -> 89.22817 | AN4: =_xll.SRS1Splines.Functions25.Linear_Interp($E$3:$E$67,$AA$3:$AA$67,AI4) -> 11.540332 | AO4: =_xll.SRS1Splines.Functions25.Linear_Interp($E$3:$E$67,$AB$3:$AB$67,AI4) -> 89.22817 | AP4: =_xll.SRS1Splines.Functions25.Linear_Interp($E$3:$E$67,$AC$3:$AC$67,AI4) -> 0 | AQ4: =_xll.SRS1Splines.Functions25.Linear_Interp($E$3:$E$67,$AD$3:$AD$67,AI4) -> 100 | AR4: =_xll.SRS1Splines.Functions25.Linear_Interp($E$3:$E$67,$AE$3:$AE$67,AI4) -> 50 | AU4: =E4 -> 1.2213997 | AV4: =AU4-0.11 -> 1.1113997 | AW4: =AU4+0.11 -> 1.3313997 | AX4: 0.0046354652 | AY4: 0.50095458 | AZ4: =(W4/100)*(C4/1000) -> 0 | BA4: =(X4/100)*(C4/1000) -> 6.505 | BB4: =((AY4*(C4/1000))-AZ4)*-1 -> -3.2587095 | BC4: =BA4-(AY4*(C4/1000)) -> 3.2462905 | BD4: =AX4 -> 0.0046354652 | BE4: 10 | BF4: 6.5044983 | BG4: =BF4/2 -> 3.2522491 | BH4: =(BG4*0.85)+BD4 -> 2.7690472 | BI4: 14.5 | BJ4: =TAN(RADIANS(BI4))*BG4 -> 0.84108881 | BK4: =SIN(RADIANS(BI4))*BG4 -> 0.81429815 | BL4: =0.02*BF4 -> 0.13008997 | BM4: =BB4-BJ4+BL4 -> -3.9697084 | BN4: =BC4-BJ4-BL4 -> 2.2751117 | BO4: =BB4-BK4 -> -4.0730077 | BP4: =BC4-BK4 -> 2.4319923 | BQ4: 2 | BR4: 1.2213997 | BS4: =BM4 -> -3.9697084 | BT4: =BN4 -> 2.2751117 | BU4: =BH4 -> 2.7690472 | BV4: 10 | BW4: =AV4 -> 1.1113997 | BX4: =AW4 -> 1.3313997 | BY4: 0 | BZ4: =BR4/10 -> 0.12213997 | CA4: 0 | CB4: 0 | CC4: 0 | CD4: 0 | CF4: 2 | CG4: =(AY4*(C4/1000))*-1 -> -3.2587095 | CH4: =CG4+(C4/1000) -> 3.2462905 | CI4: =CG4-BJ4 -> -4.0997983 | CJ4: =CH4-BJ4 -> 2.4052017 | CK4: =0.75*CG4 -> -2.4440321 | CL4: =0.75*CH4 -> 2.4347179 | CN4: =AU4-0.5 -> 0.72139968 | CO4: =AU4+0.5 -> 1.7213997
A5: -3252.5 | B5: 3252.5 | C5: =(A5*-1)+B5 -> 6505 | D5: 0.021276596 | E5: =D5*122.1399685 -> 2.5987227 | F5: 2 | G5: -2569.5612 | H5: 2611.8484 | I5: -2617.4867 | J5: 2659.7739 | K5: 5277.2606 | L5: -2617.4867 | M5: 2659.7739 | N5: 5277.2606 | O5: 0 | P5: 0 | Q5: 0 | R5: 0 | S5: 0 | T5: 0 | U5: 0 | W5: =(((A5-G5)*-1)/(C5/100)) -> 10.498675 | X5: =(((A5*-1)+H5)/(C5/100)) -> 90.151397 | Y5: =(((A5-I5)*-1)/(C5/100)) -> 9.7619262 | Z5: =(((A5*-1)+J5)/(C5/100)) -> 90.888147 | AA5: =(((A5-L5)*-1)/(C5/100)) -> 9.7619262 | AB5: =(((A5*-1)+M5)/(C5/100)) -> 90.888147 | AC5: =(O5/(C5/100)) -> 0 | AD5: =((C5-P5)/(C5/100)) -> 100 | AE5: =(((A5*-1)+Q5)/(C5/100)) -> 50 | AH5: 3 | AI5: 5.2919872 | AJ5: =_xll.SRS1Splines.Functions25.Linear_Interp($E$3:$E$67,$W$3:$W$67,AI5) -> 31.028143 | AK5: =_xll.SRS1Splines.Functions25.Linear_Interp($E$3:$E$67,$X$3:$X$67,AI5) -> 70.893104 | AL5: =_xll.SRS1Splines.Functions25.Linear_Interp($E$3:$E$67,$Y$3:$Y$67,AI5) -> 28.850729 | AM5: =_xll.SRS1Splines.Functions25.Linear_Interp($E$3:$E$67,$Z$3:$Z$67,AI5) -> 73.070518 | AN5: =_xll.SRS1Splines.Functions25.Linear_Interp($E$3:$E$67,$AA$3:$AA$67,AI5) -> 28.850729 | AO5: =_xll.SRS1Splines.Functions25.Linear_Interp($E$3:$E$67,$AB$3:$AB$67,AI5) -> 73.070518 | AP5: =_xll.SRS1Splines.Functions25.Linear_Interp($E$3:$E$67,$AC$3:$AC$67,AI5) -> 0 | AQ5: =_xll.SRS1Splines.Functions25.Linear_Interp($E$3:$E$67,$AD$3:$AD$67,AI5) -> 100 | AR5: =_xll.SRS1Splines.Functions25.Linear_Interp($E$3:$E$67,$AE$3:$AE$67,AI5) -> 50 | AU5: =E5 -> 2.5987227 | AV5: =AU5-0.11 -> 2.4887227 | AW5: =AU5+0.11 -> 2.7087227 | AX5: 0.0099455352 | AY5: 0.50107829 | AZ5: =(W5/100)*(C5/1000) -> 0.68293883 | BA5: =(X5/100)*(C5/1000) -> 5.8643484 | BB5: =((AY5*(C5/1000))-AZ5)*-1 -> -2.5765755 | BC5: =BA5-(AY5*(C5/1000)) -> 2.6048341 | BD5: =AX5 -> 0.0099455352 | BE5: 10 | BF5: 6.5039797 | BG5: =BF5/2 -> 3.2519899 | BH5: =(BG5*0.85)+BD5 -> 2.7741369 | BI5: 14.5 | BJ5: =TAN(RADIANS(BI5))*BG5 -> 0.84102176 | BK5: =SIN(RADIANS(BI5))*BG5 -> 0.81423323 | BL5: =0.02*BF5 -> 0.13007959 | BM5: =BB5-BJ5+BL5 -> -3.2875176 | BN5: =BC5-BJ5-BL5 -> 1.6337328 | BO5: =BB5-BK5 -> -3.3908087 | BP5: =BC5-BK5 -> 1.7906009 | BQ5: 3 | BR5: 2.5987227 | BS5: =BM5 -> -3.2875176 | BT5: =BN5 -> 1.6337328 | BU5: =BH5 -> 2.7741369 | BV5: 10 | BW5: =AV5 -> 2.4887227 | BX5: =AW5 -> 2.7087227 | BY5: 0 | BZ5: =BR5/10 -> 0.25987227 | CA5: 0 | CB5: 0 | CC5: 0 | CD5: 0 | CF5: 3 | CG5: =(AY5*(C5/1000))*-1 -> -3.2595143 | CH5: =CG5+(C5/1000) -> 3.2454857 | CI5: =CG5-BJ5 -> -4.1005361 | CJ5: =CH5-BJ5 -> 2.4044639 | CK5: =0.75*CG5 -> -2.4446357 | CL5: =0.75*CH5 -> 2.4341143 | CN5: =AU5-0.5 -> 2.0987227 | CO5: =AU5+0.5 -> 3.0987227
A6: -3252.5 | B6: 3252.5 | C6: =(A6*-1)+B6 -> 6505 | D6: 0.025 | E6: =D6*122.1399685 -> 3.0534992 | F6: 2 | G6: -2344.0625 | H6: 2400.3125 | I6: -2407.8125 | J6: 2464.0625 | K6: 4871.875 | L6: -2407.8125 | M6: 2464.0625 | N6: 4871.875 | O6: 0 | P6: 0 | Q6: 0 | R6: 0 | S6: 0 | T6: 0 | U6: 0 | W6: =(((A6-G6)*-1)/(C6/100)) -> 13.965219 | X6: =(((A6*-1)+H6)/(C6/100)) -> 86.8995 | Y6: =(((A6-I6)*-1)/(C6/100)) -> 12.985204 | Z6: =(((A6*-1)+J6)/(C6/100)) -> 87.879516 | AA6: =(((A6-L6)*-1)/(C6/100)) -> 12.985204 | AB6: =(((A6*-1)+M6)/(C6/100)) -> 87.879516 | AC6: =(O6/(C6/100)) -> 0 | AD6: =((C6-P6)/(C6/100)) -> 100 | AE6: =(((A6*-1)+Q6)/(C6/100)) -> 50 | AH6: 4 | AI6: 7.734334 | AJ6: =_xll.SRS1Splines.Functions25.Linear_Interp($E$3:$E$67,$W$3:$W$67,AI6) -> 37.272981 | AK6: =_xll.SRS1Splines.Functions25.Linear_Interp($E$3:$E$67,$X$3:$X$67,AI6) -> 64.844178 | AL6: =_xll.SRS1Splines.Functions25.Linear_Interp($E$3:$E$67,$Y$3:$Y$67,AI6) -> 34.660706 | AM6: =_xll.SRS1Splines.Functions25.Linear_Interp($E$3:$E$67,$Z$3:$Z$67,AI6) -> 67.456452 | AN6: =_xll.SRS1Splines.Functions25.Linear_Interp($E$3:$E$67,$AA$3:$AA$67,AI6) -> 34.660706 | AO6: =_xll.SRS1Splines.Functions25.Linear_Interp($E$3:$E$67,$AB$3:$AB$67,AI6) -> 67.456452 | AP6: =_xll.SRS1Splines.Functions25.Linear_Interp($E$3:$E$67,$AC$3:$AC$67,AI6) -> 0 | AQ6: =_xll.SRS1Splines.Functions25.Linear_Interp($E$3:$E$67,$AD$3:$AD$67,AI6) -> 100 | AR6: =_xll.SRS1Splines.Functions25.Linear_Interp($E$3:$E$67,$AE$3:$AE$67,AI6) -> 49.910502 | AU6: =E6 -> 3.0534992 | AV6: =AU6-0.11 -> 2.9434992 | AW6: =AU6+0.11 -> 3.1634992 | AX6: 0.011862881 | AY6: 0.5010597 | AZ6: =(W6/100)*(C6/1000) -> 0.9084375 | BA6: =(X6/100)*(C6/1000) -> 5.6528125 | BB6: =((AY6*(C6/1000))-AZ6)*-1 -> -2.3509558 | BC6: =BA6-(AY6*(C6/1000)) -> 2.3934192 | BD6: =AX6 -> 0.011862881 | BE6: 10 | BF6: 6.4964012 | BG6: =BF6/2 -> 3.2482006 | BH6: =(BG6*0.85)+BD6 -> 2.7728334 | BI6: 14.5 | BJ6: =TAN(RADIANS(BI6))*BG6 -> 0.84004179 | BK6: =SIN(RADIANS(BI6))*BG6 -> 0.81328448 | BL6: =0.02*BF6 -> 0.12992802 | BM6: =BB6-BJ6+BL6 -> -3.0610696 | BN6: =BC6-BJ6-BL6 -> 1.4234494 | BO6: =BB6-BK6 -> -3.1642403 | BP6: =BC6-BK6 -> 1.5801347 | BQ6: 4 | BR6: 3.0534992 | BS6: =BM6 -> -3.0610696 | BT6: =BN6 -> 1.4234494 | BU6: =BH6 -> 2.7728334 | BV6: 10 | BW6: =AV6 -> 2.9434992 | BX6: =AW6 -> 3.1634992 | BY6: 0 | BZ6: =BR6/10 -> 0.30534992 | CA6: 0 | CB6: 0 | CC6: 0 | CD6: 0 | CF6: 4 | CG6: =(AY6*(C6/1000))*-1 -> -3.2593933 | CH6: =CG6+(C6/1000) -> 3.2456067 | CI6: =CG6-BJ6 -> -4.0994351 | CJ6: =CH6-BJ6 -> 2.4055649 | CK6: =0.75*CG6 -> -2.444545 | CL6: =0.75*CH6 -> 2.434205 | CN6: =AU6-0.5 -> 2.5534992 | CO6: =AU6+0.5 -> 3.5534992
A7: -3252.5 | B7: 3252.5 | C7: =(A7*-1)+B7 -> 6505 | D7: 0.042553191 | E7: =D7*122.1399685 -> 5.1974455 | F7: 2 | G7: -1280.9973 | H7: 1403.0718 | I7: -1419.3484 | J7: 1541.4229 | K7: 2960.7713 | L7: -1419.3484 | M7: 1541.4229 | N7: 2960.7713 | O7: 0 | P7: 0 | Q7: 0 | R7: 0 | S7: 0 | T7: 0 | U7: 0 | W7: =(((A7-G7)*-1)/(C7/100)) -> 30.307497 | X7: =(((A7*-1)+H7)/(C7/100)) -> 71.569128 | Y7: =(((A7-I7)*-1)/(C7/100)) -> 28.180655 | Z7: =(((A7*-1)+J7)/(C7/100)) -> 73.69597 | AA7: =(((A7-L7)*-1)/(C7/100)) -> 28.180655 | AB7: =(((A7*-1)+M7)/(C7/100)) -> 73.69597 | AC7: =(O7/(C7/100)) -> 0 | AD7: =((C7-P7)/(C7/100)) -> 100 | AE7: =(((A7*-1)+Q7)/(C7/100)) -> 50 | AH7: 5 | AI7: 10.176681 | AJ7: =_xll.SRS1Splines.Functions25.Linear_Interp($E$3:$E$67,$W$3:$W$67,AI7) -> 37.431937 | AK7: =_xll.SRS1Splines.Functions25.Linear_Interp($E$3:$E$67,$X$3:$X$67,AI7) -> 64.381694 | AL7: =_xll.SRS1Splines.Functions25.Linear_Interp($E$3:$E$67,$Y$3:$Y$67,AI7) -> 34.84448 | AM7: =_xll.SRS1Splines.Functions25.Linear_Interp($E$3:$E$67,$Z$3:$Z$67,AI7) -> 66.969151 | AN7: =_xll.SRS1Splines.Functions25.Linear_Interp($E$3:$E$67,$AA$3:$AA$67,AI7) -> 34.84448 | AO7: =_xll.SRS1Splines.Functions25.Linear_Interp($E$3:$E$67,$AB$3:$AB$67,AI7) -> 66.969151 | AP7: =_xll.SRS1Splines.Functions25.Linear_Interp($E$3:$E$67,$AC$3:$AC$67,AI7) -> 0 | AQ7: =_xll.SRS1Splines.Functions25.Linear_Interp($E$3:$E$67,$AD$3:$AD$67,AI7) -> 100 | AR7: =_xll.SRS1Splines.Functions25.Linear_Interp($E$3:$E$67,$AE$3:$AE$67,AI7) -> 49.776182 | AU7: =E7 -> 5.1974455 | AV7: =AU7-0.11 -> 5.0874455 | AW7: =AU7+0.11 -> 5.3074455 | AX7: 0.021853535 | AY7: 0.5006271 | AZ7: =(W7/100)*(C7/1000) -> 1.9715027 | BA7: =(X7/100)*(C7/1000) -> 4.6555718 | BB7: =((AY7*(C7/1000))-AZ7)*-1 -> -1.2850766 | BC7: =BA7-(AY7*(C7/1000)) -> 1.3989925 | BD7: =AX7 -> 0.021853535 | BE7: 10 | BF7: 6.4176928 | BG7: =BF7/2 -> 3.2088464 | BH7: =(BG7*0.85)+BD7 -> 2.749373 | BI7: 14.5 | BJ7: =TAN(RADIANS(BI7))*BG7 -> 0.82986411 | BK7: =SIN(RADIANS(BI7))*BG7 -> 0.80343098 | BL7: =0.02*BF7 -> 0.12835386 | BM7: =BB7-BJ7+BL7 -> -1.9865869 | BN7: =BC7-BJ7-BL7 -> 0.44077458 | BO7: =BB7-BK7 -> -2.0885076 | BP7: =BC7-BK7 -> 0.59556157 | BQ7: 5 | BR7: 5.1974455 | BS7: =BM7 -> -1.9865869 | BT7: =BN7 -> 0.44077458 | BU7: =BH7 -> 2.749373 | BV7: 10 | BW7: =AV7 -> 5.0874455 | BX7: =AW7 -> 5.3074455 | BY7: 0 | BZ7: =BR7/10 -> 0.51974455 | CA7: 0 | CB7: 0 | CC7: 0 | CD7: 0 | CF7: 5 | CG7: =(AY7*(C7/1000))*-1 -> -3.2565793 | CH7: =CG7+(C7/1000) -> 3.2484207 | CI7: =CG7-BJ7 -> -4.0864434 | CJ7: =CH7-BJ7 -> 2.4185566 | CK7: =0.75*CG7 -> -2.4424344 | CL7: =0.75*CH7 -> 2.4363156 | CN7: =AU7-0.5 -> 4.6974455 | CO7: =AU7+0.5 -> 5.6974455
A8: -3252.5 | B8: 3252.5 | C8: =(A8*-1)+B8 -> 6505 | D8: 0.05 | E8: =D8*122.1399685 -> 6.1069984 | F8: 2 | G8: -830 | H8: 980 | I8: -1000 | J8: 1150 | K8: 2150 | L8: -1000 | M8: 1150 | N8: 2150 | O8: 0 | P8: 0 | Q8: 0 | R8: 0 | S8: 0 | T8: 0 | U8: 0 | W8: =(((A8-G8)*-1)/(C8/100)) -> 37.240584 | X8: =(((A8*-1)+H8)/(C8/100)) -> 65.065334 | Y8: =(((A8-I8)*-1)/(C8/100)) -> 34.62721 | Z8: =(((A8*-1)+J8)/(C8/100)) -> 67.678709 | AA8: =(((A8-L8)*-1)/(C8/100)) -> 34.62721 | AB8: =(((A8*-1)+M8)/(C8/100)) -> 67.678709 | AC8: =(O8/(C8/100)) -> 0 | AD8: =((C8-P8)/(C8/100)) -> 100 | AE8: =(((A8*-1)+Q8)/(C8/100)) -> 50 | AH8: 6 | AI8: 12.620442 | AJ8: =_xll.SRS1Splines.Functions25.Linear_Interp($E$3:$E$67,$W$3:$W$67,AI8) -> 37.100033 | AK8: =_xll.SRS1Splines.Functions25.Linear_Interp($E$3:$E$67,$X$3:$X$67,AI8) -> 62.818242 | AL8: =_xll.SRS1Splines.Functions25.Linear_Interp($E$3:$E$67,$Y$3:$Y$67,AI8) -> 34.597448 | AM8: =_xll.SRS1Splines.Functions25.Linear_Interp($E$3:$E$67,$Z$3:$Z$67,AI8) -> 65.320827 | AN8: =_xll.SRS1Splines.Functions25.Linear_Interp($E$3:$E$67,$AA$3:$AA$67,AI8) -> 34.597448 | AO8: =_xll.SRS1Splines.Functions25.Linear_Interp($E$3:$E$67,$AB$3:$AB$67,AI8) -> 65.320827 | AP8: =_xll.SRS1Splines.Functions25.Linear_Interp($E$3:$E$67,$AC$3:$AC$67,AI8) -> 7.0141418 | AQ8: =_xll.SRS1Splines.Functions25.Linear_Interp($E$3:$E$67,$AD$3:$AD$67,AI8) -> 88.175708 | AR8: =_xll.SRS1Splines.Functions25.Linear_Interp($E$3:$E$67,$AE$3:$AE$67,AI8) -> 48.87191 | AU8: =E8 -> 6.1069984 | AV8: =AU8-0.11 -> 5.9969984 | AW8: =AU8+0.11 -> 6.2169984 | AX8: 0.026131433 | AY8: 0.50099774 | AZ8: =(W8/100)*(C8/1000) -> 2.4225 | BA8: =(X8/100)*(C8/1000) -> 4.2325 | BB8: =((AY8*(C8/1000))-AZ8)*-1 -> -0.83649028 | BC8: =BA8-(AY8*(C8/1000)) -> 0.97350972 | BD8: =AX8 -> 0.026131433 | BE8: 10 | BF8: 6.3383559 | BG8: =BF8/2 -> 3.1691779 | BH8: =(BG8*0.85)+BD8 -> 2.7199327 | BI8: 14.5 | BJ8: =TAN(RADIANS(BI8))*BG8 -> 0.81960514 | BK8: =SIN(RADIANS(BI8))*BG8 -> 0.79349879 | BL8: =0.02*BF8 -> 0.12676712 | BM8: =BB8-BJ8+BL8 -> -1.5293283 | BN8: =BC8-BJ8-BL8 -> 0.027137457 | BO8: =BB8-BK8 -> -1.6299891 | BP8: =BC8-BK8 -> 0.18001093 | BQ8: 6 | BR8: 6.1069984 | BS8: =BM8 -> -1.5293283 | BT8: =BN8 -> 0.027137457 | BU8: =BH8 -> 2.7199327 | BV8: 10 | BW8: =AV8 -> 5.9969984 | BX8: =AW8 -> 6.2169984 | BY8: 0 | BZ8: =BR8/10 -> 0.61069984 | CA8: 0 | CB8: 0 | CC8: 0 | CD8: 0 | CF8: 6 | CG8: =(AY8*(C8/1000))*-1 -> -3.2589903 | CH8: =CG8+(C8/1000) -> 3.2460097 | CI8: =CG8-BJ8 -> -4.0785954 | CJ8: =CH8-BJ8 -> 2.4264046 | CK8: =0.75*CG8 -> -2.4442427 | CL8: =0.75*CH8 -> 2.4345073 | CN8: =AU8-0.5 -> 5.6069984 | CO8: =AU8+0.5 -> 6.6069984
A9: -3247.8759 | B9: 3259.9673 | C9: =(A9*-1)+B9 -> 6507.8432 | D9: 0.063829787 | E9: =D9*122.1399685 -> 7.7961682 | F9: 2 | G9: -822.12866 | H9: 971.5346 | I9: -992.12866 | J9: 1141.5346 | K9: 2133.6633 | L9: -992.12866 | M9: 1141.5346 | N9: 2133.6633 | O9: 0 | P9: 0 | Q9: 0 | R9: 0 | S9: 0 | T9: 0 | U9: 0 | W9: =(((A9-G9)*-1)/(C9/100)) -> 37.274212 | X9: =(((A9*-1)+H9)/(C9/100)) -> 64.835774 | Y9: =(((A9-I9)*-1)/(C9/100)) -> 34.661979 | Z9: =(((A9*-1)+J9)/(C9/100)) -> 67.448007 | AA9: =(((A9-L9)*-1)/(C9/100)) -> 34.661979 | AB9: =(((A9*-1)+M9)/(C9/100)) -> 67.448007 | AC9: =(O9/(C9/100)) -> 0 | AD9: =((C9-P9)/(C9/100)) -> 100 | AE9: =(((A9*-1)+Q9)/(C9/100)) -> 49.907102 | AH9: 7 | AI9: 15.061374 | AJ9: =_xll.SRS1Splines.Functions25.Linear_Interp($E$3:$E$67,$W$3:$W$67,AI9) -> 36.187105 | AK9: =_xll.SRS1Splines.Functions25.Linear_Interp($E$3:$E$67,$X$3:$X$67,AI9) -> 60.356501 | AL9: =_xll.SRS1Splines.Functions25.Linear_Interp($E$3:$E$67,$Y$3:$Y$67,AI9) -> 33.803284 | AM9: =_xll.SRS1Splines.Functions25.Linear_Interp($E$3:$E$67,$Z$3:$Z$67,AI9) -> 62.740322 | AN9: =_xll.SRS1Splines.Functions25.Linear_Interp($E$3:$E$67,$AA$3:$AA$67,AI9) -> 33.803284 | AO9: =_xll.SRS1Splines.Functions25.Linear_Interp($E$3:$E$67,$AB$3:$AB$67,AI9) -> 62.740322 | AP9: =_xll.SRS1Splines.Functions25.Linear_Interp($E$3:$E$67,$AC$3:$AC$67,AI9) -> 6.4036629 | AQ9: =_xll.SRS1Splines.Functions25.Linear_Interp($E$3:$E$67,$AD$3:$AD$67,AI9) -> 88.695479 | AR9: =_xll.SRS1Splines.Functions25.Linear_Interp($E$3:$E$67,$AE$3:$AE$67,AI9) -> 47.242141 | AU9: =E9 -> 7.7961682 | AV9: =AU9-0.11 -> 7.6861682 | AW9: =AU9+0.11 -> 7.9061682 | AX9: 0.034117282 | AY9: 0.50169004 | AZ9: =(W9/100)*(C9/1000) -> 2.4257472 | BA9: =(X9/100)*(C9/1000) -> 4.2194105 | BB9: =((AY9*(C9/1000))-AZ9)*-1 -> -0.83917287 | BC9: =BA9-(AY9*(C9/1000)) -> 0.95449039 | BD9: =AX9 -> 0.034117282 | BE9: 10 | BF9: 6.1796126 | BG9: =BF9/2 -> 3.0898063 | BH9: =(BG9*0.85)+BD9 -> 2.6604526 | BI9: 14.499616 | BJ9: =TAN(RADIANS(BI9))*BG9 -> 0.79905615 | BK9: =SIN(RADIANS(BI9))*BG9 -> 0.77360566 | BL9: =0.02*BF9 -> 0.12359225 | BM9: =BB9-BJ9+BL9 -> -1.5146368 | BN9: =BC9-BJ9-BL9 -> 0.031841994 | BO9: =BB9-BK9 -> -1.6127785 | BP9: =BC9-BK9 -> 0.18088473 | BQ9: 7 | BR9: 7.7961682 | BS9: =BM9 -> -1.5146368 | BT9: =BN9 -> 0.031841994 | BU9: =BH9 -> 2.6604526 | BV9: 10 | BW9: =AV9 -> 7.6861682 | BX9: =AW9 -> 7.9061682 | BY9: 0 | BZ9: =BR9/10 -> 0.77961682 | CA9: 0 | CB9: 0 | CC9: 0 | CD9: 0 | CF9: 7 | CG9: =(AY9*(C9/1000))*-1 -> -3.2649201 | CH9: =CG9+(C9/1000) -> 3.242923 | CI9: =CG9-BJ9 -> -4.0639763 | CJ9: =CH9-BJ9 -> 2.4438669 | CK9: =0.75*CG9 -> -2.4486901 | CL9: =0.75*CH9 -> 2.4321923 | CN9: =AU9-0.5 -> 7.2961682 | CO9: =AU9+0.5 -> 8.2961682
A10: -3270.4664 | B10: 3299.9487 | C10: =(A10*-1)+B10 -> 6570.4151 | D10: 0.0834 | E10: =D10*122.1399685 -> 10.186473 | F10: 2 | G10: -810.99012 | H10: 959.55541 | I10: -980.99012 | J10: 1129.5554 | K10: 2110.5455 | L10: -980.99012 | M10: 1129.5554 | N10: 2110.5455 | O10: 0 | P10: 0 | Q10: 0 | R10: 0 | S10: 0 | T10: 0 | U10: 0 | W10: =(((A10-G10)*-1)/(C10/100)) -> 37.432586 | X10: =(((A10*-1)+H10)/(C10/100)) -> 64.379826 | Y10: =(((A10-I10)*-1)/(C10/100)) -> 34.84523 | Z10: =(((A10*-1)+J10)/(C10/100)) -> 66.967182 | AA10: =(((A10-L10)*-1)/(C10/100)) -> 34.84523 | AB10: =(((A10*-1)+M10)/(C10/100)) -> 66.967182 | AC10: =(O10/(C10/100)) -> 0 | AD10: =((C10-P10)/(C10/100)) -> 100 | AE10: =(((A10*-1)+Q10)/(C10/100)) -> 49.775644 | AH10: 8 | AI10: 17.502307 | AJ10: =_xll.SRS1Splines.Functions25.Linear_Interp($E$3:$E$67,$W$3:$W$67,AI10) -> 35.276906 | AK10: =_xll.SRS1Splines.Functions25.Linear_Interp($E$3:$E$67,$X$3:$X$67,AI10) -> 57.889841 | AL10: =_xll.SRS1Splines.Functions25.Linear_Interp($E$3:$E$67,$Y$3:$Y$67,AI10) -> 33.015711 | AM10: =_xll.SRS1Splines.Functions25.Linear_Interp($E$3:$E$67,$Z$3:$Z$67,AI10) -> 60.151036 | AN10: =_xll.SRS1Splines.Functions25.Linear_Interp($E$3:$E$67,$AA$3:$AA$67,AI10) -> 33.015711 | AO10: =_xll.SRS1Splines.Functions25.Linear_Interp($E$3:$E$67,$AB$3:$AB$67,AI10) -> 60.151036 | AP10: =_xll.SRS1Splines.Functions25.Linear_Interp($E$3:$E$67,$AC$3:$AC$67,AI10) -> 6.0817226 | AQ10: =_xll.SRS1Splines.Functions25.Linear_Interp($E$3:$E$67,$AD$3:$AD$67,AI10) -> 89.509806 | AR10: =_xll.SRS1Splines.Functions25.Linear_Interp($E$3:$E$67,$AE$3:$AE$67,AI10) -> 45.612372 | AU10: =E10 -> 10.186473 | AV10: =AU10-0.11 -> 10.076473 | AW10: =AU10+0.11 -> 10.296473 | AX10: 0.046641065 | AY10: 0.49836702 | AZ10: =(W10/100)*(C10/1000) -> 2.4594763 | BA10: =(X10/100)*(C10/1000) -> 4.2300218 | BB10: =((AY10*(C10/1000))-AZ10)*-1 -> -0.81500192 | BC10: =BA10-(AY10*(C10/1000)) -> 0.95554361 | BD10: =AX10 -> 0.046641065 | BE10: 10 | BF10: 5.8966772 | BG10: =BF10/2 -> 2.9483386 | BH10: =(BG10*0.85)+BD10 -> 2.5527289 | BI10: 14.48432 | BJ10: =TAN(RADIANS(BI10))*BG10 -> 0.76163142 | BK10: =SIN(RADIANS(BI10))*BG10 -> 0.73742382 | BL10: =0.02*BF10 -> 0.11793354 | BM10: =BB10-BJ10+BL10 -> -1.4586998 | BN10: =BC10-BJ10-BL10 -> 0.075978646 | BO10: =BB10-BK10 -> -1.5524257 | BP10: =BC10-BK10 -> 0.21811979 | BQ10: 8 | BR10: 10.186473 | BS10: =BM10 -> -1.4586998 | BT10: =BN10 -> 0.075978646 | BU10: =BH10 -> 2.5527289 | BV10: 10 | BW10: =AV10 -> 10.076473 | BX10: =AW10 -> 10.296473 | BY10: 0 | BZ10: =BR10/10 -> 1.0186473 | CA10: 0 | CB10: 0 | CC10: 0 | CD10: 0 | CF10: 8 | CG10: =(AY10*(C10/1000))*-1 -> -3.2744782 | CH10: =CG10+(C10/1000) -> 3.2959369 | CI10: =CG10-BJ10 -> -4.0361096 | CJ10: =CH10-BJ10 -> 2.5343055 | CK10: =0.75*CG10 -> -2.4558587 | CL10: =0.75*CH10 -> 2.4719527 | CN10: =AU10-0.5 -> 9.6864734 | CO10: =AU10+0.5 -> 10.686473
A11: -3274.4852 | B11: 3312.6059 | C11: =(A11*-1)+B11 -> 6587.0912 | D11: 0.085106383 | E11: =D11*122.1399685 -> 10.394891 | F11: 2 | G11: -810.01892 | H11: 958.51091 | I11: -980.01892 | J11: 1128.5109 | K11: 2108.5298 | L11: -980.01892 | M11: 1128.5109 | N11: 2108.5298 | O11: 0 | P11: 0 | Q11: 0 | R11: 0 | S11: 0 | T11: 0 | U11: 0 | W11: =(((A11-G11)*-1)/(C11/100)) -> 37.413575 | X11: =(((A11*-1)+H11)/(C11/100)) -> 64.261994 | Y11: =(((A11-I11)*-1)/(C11/100)) -> 34.83277 | Z11: =(((A11*-1)+J11)/(C11/100)) -> 66.8428 | AA11: =(((A11-L11)*-1)/(C11/100)) -> 34.83277 | AB11: =(((A11*-1)+M11)/(C11/100)) -> 66.8428 | AC11: =(O11/(C11/100)) -> 0 | AD11: =((C11-P11)/(C11/100)) -> 100 | AE11: =(((A11*-1)+Q11)/(C11/100)) -> 49.710641 | AH11: 9 | AI11: 19.946068 | AJ11: =_xll.SRS1Splines.Functions25.Linear_Interp($E$3:$E$67,$W$3:$W$67,AI11) -> 34.325933 | AK11: =_xll.SRS1Splines.Functions25.Linear_Interp($E$3:$E$67,$X$3:$X$67,AI11) -> 55.471137 | AL11: =_xll.SRS1Splines.Functions25.Linear_Interp($E$3:$E$67,$Y$3:$Y$67,AI11) -> 32.18134 | AM11: =_xll.SRS1Splines.Functions25.Linear_Interp($E$3:$E$67,$Z$3:$Z$67,AI11) -> 57.61573 | AN11: =_xll.SRS1Splines.Functions25.Linear_Interp($E$3:$E$67,$AA$3:$AA$67,AI11) -> 32.18134 | AO11: =_xll.SRS1Splines.Functions25.Linear_Interp($E$3:$E$67,$AB$3:$AB$67,AI11) -> 57.61573 | AP11: =_xll.SRS1Splines.Functions25.Linear_Interp($E$3:$E$67,$AC$3:$AC$67,AI11) -> 5.8511144 | AQ11: =_xll.SRS1Splines.Functions25.Linear_Interp($E$3:$E$67,$AD$3:$AD$67,AI11) -> 90.350819 | AR11: =_xll.SRS1Splines.Functions25.Linear_Interp($E$3:$E$67,$AE$3:$AE$67,AI11) -> 43.983089 | AU11: =E11 -> 10.394891 | AV11: =AU11-0.11 -> 10.284891 | AW11: =AU11+0.11 -> 10.504891 | AX11: 0.047859514 | AY11: 0.49797982 | AZ11: =(W11/100)*(C11/1000) -> 2.4644663 | BA11: =(X11/100)*(C11/1000) -> 4.2329961 | BB11: =((AY11*(C11/1000))-AZ11)*-1 -> -0.81577213 | BC11: =BA11-(AY11*(C11/1000)) -> 0.9527577 | BD11: =AX11 -> 0.047859514 | BE11: 10 | BF11: 5.8766291 | BG11: =BF11/2 -> 2.9383145 | BH11: =(BG11*0.85)+BD11 -> 2.5454269 | BI11: 14.473372 | BJ11: =TAN(RADIANS(BI11))*BG11 -> 0.75844307 | BK11: =SIN(RADIANS(BI11))*BG11 -> 0.73437304 | BL11: =0.02*BF11 -> 0.11753258 | BM11: =BB11-BJ11+BL11 -> -1.4566826 | BN11: =BC11-BJ11-BL11 -> 0.076782054 | BO11: =BB11-BK11 -> -1.5501452 | BP11: =BC11-BK11 -> 0.21838466 | BQ11: 9 | BR11: 10.394891 | BS11: =BM11 -> -1.4566826 | BT11: =BN11 -> 0.076782054 | BU11: =BH11 -> 2.5454269 | BV11: 10 | BW11: =AV11 -> 10.284891 | BX11: =AW11 -> 10.504891 | BY11: 0 | BZ11: =BR11/10 -> 1.0394891 | CA11: 0 | CB11: 0 | CC11: 0 | CD11: 0 | CF11: 9 | CG11: =(AY11*(C11/1000))*-1 -> -3.2802384 | CH11: =CG11+(C11/1000) -> 3.3068527 | CI11: =CG11-BJ11 -> -4.0386815 | CJ11: =CH11-BJ11 -> 2.5484097 | CK11: =0.75*CG11 -> -2.4601788 | CL11: =0.75*CH11 -> 2.4801395 | CN11: =AU11-0.5 -> 9.8948909 | CO11: =AU11+0.5 -> 10.894891
A12: -3314.6938 | B12: 3430.2638 | C12: =(A12*-1)+B12 -> 6744.9575 | D12: 0.1 | E12: =D12*122.1399685 -> 12.213997 | F12: 2 | G12: -801.5421 | H12: 949.39433 | I12: -971.5421 | J12: 1119.3943 | K12: 2090.9364 | L12: -971.5421 | M12: 1119.3943 | N12: 2090.9364 | O12: 483.1 | P12: 799.4 | Q12: 0 | R12: 0 | S12: 0 | T12: 0 | U12: 0 | W12: =(((A12-G12)*-1)/(C12/100)) -> 37.259711 | X12: =(((A12*-1)+H12)/(C12/100)) -> 63.218902 | Y12: =(((A12-I12)*-1)/(C12/100)) -> 34.739309 | Z12: =(((A12*-1)+J12)/(C12/100)) -> 65.739303 | AA12: =(((A12-L12)*-1)/(C12/100)) -> 34.739309 | AB12: =(((A12*-1)+M12)/(C12/100)) -> 65.739303 | AC12: =(O12/(C12/100)) -> 7.1623876 | AD12: =((C12-P12)/(C12/100)) -> 88.148183 | AE12: =(((A12*-1)+Q12)/(C12/100)) -> 49.143286 | AH12: 10 | AI12: 21.982536 | AJ12: =_xll.SRS1Splines.Functions25.Linear_Interp($E$3:$E$67,$W$3:$W$67,AI12) -> 33.552934 | AK12: =_xll.SRS1Splines.Functions25.Linear_Interp($E$3:$E$67,$X$3:$X$67,AI12) -> 53.710722 | AL12: =_xll.SRS1Splines.Functions25.Linear_Interp($E$3:$E$67,$Y$3:$Y$67,AI12) -> 31.484513 | AM12: =_xll.SRS1Splines.Functions25.Linear_Interp($E$3:$E$67,$Z$3:$Z$67,AI12) -> 55.779143 | AN12: =_xll.SRS1Splines.Functions25.Linear_Interp($E$3:$E$67,$AA$3:$AA$67,AI12) -> 31.484513 | AO12: =_xll.SRS1Splines.Functions25.Linear_Interp($E$3:$E$67,$AB$3:$AB$67,AI12) -> 55.779143 | AP12: =_xll.SRS1Splines.Functions25.Linear_Interp($E$3:$E$67,$AC$3:$AC$67,AI12) -> 5.7288 | AQ12: =_xll.SRS1Splines.Functions25.Linear_Interp($E$3:$E$67,$AD$3:$AD$67,AI12) -> 90.949134 | AR12: =_xll.SRS1Splines.Functions25.Linear_Interp($E$3:$E$67,$AE$3:$AE$67,AI12) -> 42.753195 | AU12: =E12 -> 12.213997 | AV12: =AU12-0.11 -> 12.103997 | AW12: =AU12+0.11 -> 12.323997 | AX12: 0.058494359 | AY12: 0.49460022 | AZ12: =(W12/100)*(C12/1000) -> 2.5131517 | BA12: =(X12/100)*(C12/1000) -> 4.2640881 | BB12: =((AY12*(C12/1000))-AZ12)*-1 -> -0.82290578 | BC12: =BA12-(AY12*(C12/1000)) -> 0.92803065 | BD12: =AX12 -> 0.058494359 | BE12: 10 | BF12: 5.6925861 | BG12: =BF12/2 -> 2.846293 | BH12: =(BG12*0.85)+BD12 -> 2.4778434 | BI12: 14.377817 | BJ12: =TAN(RADIANS(BI12))*BG12 -> 0.7296293 | BK12: =SIN(RADIANS(BI12))*BG12 -> 0.70677685 | BL12: =0.02*BF12 -> 0.11385172 | BM12: =BB12-BJ12+BL12 -> -1.4386834 | BN12: =BC12-BJ12-BL12 -> 0.084549623 | BO12: =BB12-BK12 -> -1.5296826 | BP12: =BC12-BK12 -> 0.22125379 | BQ12: 10 | BR12: 12.213997 | BS12: =BM12 -> -1.4386834 | BT12: =BN12 -> 0.084549623 | BU12: =BH12 -> 2.4778434 | BV12: 10 | BW12: =AV12 -> 12.103997 | BX12: =AW12 -> 12.323997 | BY12: 0 | BZ12: =BR12/10 -> 1.2213997 | CA12: 0 | CB12: 0 | CC12: 0 | CD12: 0 | CF12: 10 | CG12: =(AY12*(C12/1000))*-1 -> -3.3360575 | CH12: =CG12+(C12/1000) -> 3.4089001 | CI12: =CG12-BJ12 -> -4.0656868 | CJ12: =CH12-BJ12 -> 2.6792708 | CK12: =0.75*CG12 -> -2.5020431 | CL12: =0.75*CH12 -> 2.5566751 | CN12: =AU12-0.5 -> 11.713997 | CO12: =AU12+0.5 -> 12.713997
